<?xml version="1.0"?>
<robot xmlns:xacro="http://www.ros.org/wiki/xacro" name="simple_mobile_platform">

<!-- CYLINDER INERTIA-->
    <xacro:macro name="cylinder_inertia" params="radius length mass *origin">
        <inertial>
            <mass value="${mass}" />
            <xacro:insert_block name="origin" />
            <inertia ixx="${0.0833333 * mass * (3 * radius * radius + length * length)}" ixy="0.0" ixz="0.0"
                     iyy="${0.0833333 * mass * (3 * radius * radius + length * length)}" iyz="0.0"
                     izz="${0.5 * mass * radius * radius}" />
        </inertial>
    </xacro:macro>

<!-- ROBOT FRAME -->
    <xacro:macro name="frame" params="name parent trans rot">
        <link name="${name}">
            <visual>
                <geometry>
                    <box size="0.6 0.4 0.3"/>
                </geometry>
            </visual>
            <collision>
                <geometry>
                    <box size="0.6 0.4 0.3"/>
                </geometry>
            </collision>
            <xacro:cylinder_inertia radius="0.3" length="0.2" mass="30">
                <origin xyz="0 0 0" rpy="0 0 0"/>
            </xacro:cylinder_inertia>
        </link>

        <joint name="${name}_joint" type="fixed">
            <parent link="${parent}"/>
            <child link="${name}"/>
            <origin rpy="${rot}" xyz="${trans}"/>
        </joint>
    </xacro:macro>

<!-- ROBOT PROPULSION WHEEL -->
    <xacro:macro name="propulsion_wheel" params="name parent trans rot">
        <link name="${name}">
            <visual>
                <geometry>
                    <cylinder radius="0.1" length="0.01"/>
                </geometry>
            </visual>
            <collision>
                <geometry>
                    <cylinder radius="0.1" length="0.01"/>
                </geometry>
            </collision>
            <xacro:cylinder_inertia radius="0.1" length="0.01" mass="1">
                <origin xyz="0 0 0" rpy="0 0 0"/>
            </xacro:cylinder_inertia>
        </link>

        <joint name="${name}_joint" type="continuous">
            <parent link="${parent}"/>
            <child link="${name}"/>
            <origin rpy="${rot}" xyz="${trans}"/>
            <axis xyz="0 0 1" />
        </joint>
    </xacro:macro>

<!-- ROBOT CASTOR WHEEL-->

    <xacro:macro name="castor_wheel" params="name parent trans rot">

        <link name="${name}_turn">
            <xacro:cylinder_inertia radius="0.1" length="0.01" mass="0.2">
                <origin xyz="0 0 0" rpy="0 0 0"/>
            </xacro:cylinder_inertia>
        </link>

        <joint name="${name}_turn_joint" type="continuous">
            <parent link="${parent}"/>
            <child link="${name}_turn"/>
            <origin rpy="${rot}" xyz="${trans}"/>
            <axis xyz="0 0 1"/>
            </joint>

        <link name="${name}_wheel">
            <visual>
                <geometry>
                    <cylinder radius="0.02" length="0.01"/>
                </geometry>
            </visual>
            <collision>
                <geometry>
                    <cylinder radius="0.02" length="0.01"/>
                </geometry>
            </collision>
            <xacro:cylinder_inertia radius="0.1" length="0.01" mass="0.3">
                <origin xyz="0 0 0" rpy="0 0 0"/>
            </xacro:cylinder_inertia>
        </link>

        <joint name="${name}_wheel_joint" type="continuous">
            <parent link="${name}_turn"/>
            <child link="${name}_wheel"/>
            <origin rpy="1.5708 0 0" xyz="-0.02 0 0"/>
            <axis xyz="0 0 1"/>
            </joint>

    </xacro:macro>

<!-- ROBOT LIDAR -->

    <xacro:macro name="lidar" params="name parent trans rot">
        <link name="${name}">
            <visual>
                <geometry>
                    <cylinder radius="0.02" length="0.05"/>
                </geometry>
            </visual>
            <collision>
                <geometry>
                    <cylinder radius="0.02" length="0.05"/>
                </geometry>
            </collision>
            <xacro:cylinder_inertia radius="0.3" length="0.2" mass="30">
                <origin xyz="0 0 0" rpy="0 0 0"/>
            </xacro:cylinder_inertia>
        </link>

        <joint name="${name}_joint" type="fixed">
            <parent link="${parent}"/>
            <child link="${name}"/>
            <origin rpy="${rot}" xyz="${trans}"/>
        </joint>
    </xacro:macro>

<!-- ASSEMBLY -->

    <link name="simple_mobile_platform"/>

    <xacro:frame
        name="frame"
        parent="simple_mobile_platform"
        trans="0 0 0"
        rot="0 0 0"
        />

    <xacro:lidar
        name="lidar"
        parent="frame"
        trans="0.2 0 0.18"
        rot="0 0 0"
        />

    <xacro:propulsion_wheel
        name="propulsion_wheel_l"
        parent="frame"
        trans="0 0.24 -0.1"
        rot="1.5708 0 0"
        />

    <xacro:propulsion_wheel
        name="propulsion_wheel_r"
        parent="frame"
        trans="0 -0.24 -0.1"
        rot="1.5708 0 0"
        />

    <xacro:castor_wheel
        name="castor_wheel_f"
        parent="frame"
        trans="0.24 0 -0.18"
        rot="0 0 0"
        />

    <xacro:castor_wheel
        name="castor_wheel_r"
        parent="frame"
        trans="-0.24 0 -0.18"
        rot="0 0 0"
        />

</robot>