<?xml version="1.0" encoding="utf-8"?>
<!-- =================================================================================== -->
<!-- |    This document was autogenerated by xacro from /home/pwalczykk-t3610/code/pytorch-training/006_simple_mobile_platform/simple_mobile_platform.xacro | -->
<!-- |    EDITING THIS FILE BY HAND IS NOT RECOMMENDED                                 | -->
<!-- =================================================================================== -->
<robot name="simple_mobile_platform">
  <!-- ROBOT CASTOR WHEEL-->
  <!-- ASSEMBLY -->
  <link name="base_link"/>
  <link name="frame">
    <visual>
      <geometry>
        <box size="0.6 0.4 0.3"/>
      </geometry>
    </visual>
    <collision>
      <geometry>
        <box size="0.6 0.4 0.3"/>
      </geometry>
    </collision>
    <inertial>
      <mass value="30"/>
      <origin rpy="0 0 0" xyz="0 0 0"/>
      <inertia ixx="0.77499969" ixy="0.0" ixz="0.0" iyy="0.77499969" iyz="0.0" izz="1.35"/>
    </inertial>
  </link>
  <joint name="frame_joint" type="fixed">
    <parent link="base_link"/>
    <child link="frame"/>
    <origin rpy="0 0 0" xyz="0 0 0"/>
  </joint>
  <link name="propulsion_wheel_l">
    <visual>
      <geometry>
        <cylinder length="0.01" radius="0.1"/>
      </geometry>
    </visual>
    <collision>
      <geometry>
        <cylinder length="0.01" radius="0.1"/>
      </geometry>
    </collision>
    <inertial>
      <mass value="1"/>
      <origin rpy="0 0 0" xyz="0 0 0"/>
      <inertia ixx="0.00250833233" ixy="0.0" ixz="0.0" iyy="0.00250833233" iyz="0.0" izz="0.005"/>
    </inertial>
  </link>
  <joint name="propulsion_wheel_l_joint" type="continuous">
    <parent link="frame"/>
    <child link="propulsion_wheel_l"/>
    <origin rpy="1.5708 0 0" xyz="0 0.24 -0.1"/>
    <axis xyz="0 0 1"/>
  </joint>
  <link name="propulsion_wheel_r">
    <visual>
      <geometry>
        <cylinder length="0.01" radius="0.1"/>
      </geometry>
    </visual>
    <collision>
      <geometry>
        <cylinder length="0.01" radius="0.1"/>
      </geometry>
    </collision>
    <inertial>
      <mass value="1"/>
      <origin rpy="0 0 0" xyz="0 0 0"/>
      <inertia ixx="0.00250833233" ixy="0.0" ixz="0.0" iyy="0.00250833233" iyz="0.0" izz="0.005"/>
    </inertial>
  </link>
  <joint name="propulsion_wheel_r_joint" type="continuous">
    <parent link="frame"/>
    <child link="propulsion_wheel_r"/>
    <origin rpy="1.5708 0 0" xyz="0 -0.24 -0.1"/>
    <axis xyz="0 0 1"/>
  </joint>
  <link name="castor_wheel_f_turn">
    <inertial>
      <mass value="0.2"/>
      <origin rpy="0 0 0" xyz="0 0 0"/>
      <inertia ixx="0.000501666466" ixy="0.0" ixz="0.0" iyy="0.000501666466" iyz="0.0" izz="0.001"/>
    </inertial>
  </link>
  <joint name="castor_wheel_f_turn_joint" type="continuous">
    <parent link="frame"/>
    <child link="castor_wheel_f_turn"/>
    <origin rpy="0 0 0" xyz="0.24 0 -0.18"/>
    <axis xyz="0 0 1"/>
  </joint>
  <link name="castor_wheel_f_wheel">
    <visual>
      <geometry>
        <cylinder length="0.01" radius="0.02"/>
      </geometry>
    </visual>
    <collision>
      <geometry>
        <cylinder length="0.01" radius="0.02"/>
      </geometry>
    </collision>
    <inertial>
      <mass value="0.3"/>
      <origin rpy="0 0 0" xyz="0 0 0"/>
      <inertia ixx="0.000752499699" ixy="0.0" ixz="0.0" iyy="0.000752499699" iyz="0.0" izz="0.0015"/>
    </inertial>
  </link>
  <joint name="castor_wheel_f_wheel_joint" type="continuous">
    <parent link="castor_wheel_f_turn"/>
    <child link="castor_wheel_f_wheel"/>
    <origin rpy="1.5708 0 0" xyz="-0.02 0 0"/>
    <axis xyz="0 0 1"/>
  </joint>
  <link name="castor_wheel_r_turn">
    <inertial>
      <mass value="0.2"/>
      <origin rpy="0 0 0" xyz="0 0 0"/>
      <inertia ixx="0.000501666466" ixy="0.0" ixz="0.0" iyy="0.000501666466" iyz="0.0" izz="0.001"/>
    </inertial>
  </link>
  <joint name="castor_wheel_r_turn_joint" type="continuous">
    <parent link="frame"/>
    <child link="castor_wheel_r_turn"/>
    <origin rpy="0 0 0" xyz="-0.24 0 -0.18"/>
    <axis xyz="0 0 1"/>
  </joint>
  <link name="castor_wheel_r_wheel">
    <visual>
      <geometry>
        <cylinder length="0.01" radius="0.02"/>
      </geometry>
    </visual>
    <collision>
      <geometry>
        <cylinder length="0.01" radius="0.02"/>
      </geometry>
    </collision>
    <inertial>
      <mass value="0.3"/>
      <origin rpy="0 0 0" xyz="0 0 0"/>
      <inertia ixx="0.000752499699" ixy="0.0" ixz="0.0" iyy="0.000752499699" iyz="0.0" izz="0.0015"/>
    </inertial>
  </link>
  <joint name="castor_wheel_r_wheel_joint" type="continuous">
    <parent link="castor_wheel_r_turn"/>
    <child link="castor_wheel_r_wheel"/>
    <origin rpy="1.5708 0 0" xyz="-0.02 0 0"/>
    <axis xyz="0 0 1"/>
  </joint>
</robot>

